Workbook

Sheet README
A1: Deep Tax Burden Study v35 | Publication Ready
A2: Fully inclusive mature replacement-year model with all validated revenue methods active. The Land Value Tax remains unchanged.
A3: Purpose | B3: Average mature replacement-year funding model for General Government, Social Security, Healthcare, and dedicated public funds.
A4: Source of truth | B4: Policy Book v91 plus user-approved revisions through Tax Overhaul v28 / Study v35.
A5: Headline revenue | B5: Operating General Treasury Revenue: $5.711T. Year 10 Total Government Revenue: $9.103T.
A6: Headline balance | B6: General Government: +$318.956B. Social Security: $0. Healthcare: +$376.509B. Year 10 consolidated surplus: +$1.080T.
A7: National Continuity Contribution | B7: 0.73% on covered enterprise value above $1M. Central assessed base: $68T. Social Security first, NIRF residual.
A8: Resident Contributor Number | B8: Noncitizens use the RCN and contribute 7% employee / 7% employer until citizenship.
A9: Citizen Data Royalty | B9: 30% of a $246.532B covered data-market base, producing $73.960B for the Citizen Wealth Fund.
A10: Luxury Tax | B10: Flat 5% on a $241.275B active market base, producing $12.064B.
A11: Expanded liquid income | B11: Includes pensions, annuities, IRA distributions, royalties, settlements, foreign cash income, and data-licensing payments.
A12: Anti-deferral | B12: 10% on covered Form 4797 gains, deferred like-kind gains, REMIC residual income, and related entity-retention methods.
A13: Industrial and behavioral revenue | B13: Outsourcing Penalty, Fair Profit Tax, Loan Scumming taxes, Protectorate Fee, Carbon Tax, and spectrum stewardship are active.
A14: Public-enterprise revenue | B14: NLA, NHDC international licensing, federal data services, laboratory licensing, industrial campuses, pipeline corridors, and commercial space services are included.
... A19: Formula integrity restored | B19: This publication restores 80 cells across 13 sheets that had been stripped to a bare equals sign in prior versions (present already in v33 Corrected and v34), plus several genuinely blank subtotal or placeholder rows (Cost_Savings_Program row 20, SS_Year_0_4_10 row 25, and three merged rows in Deficit_Views). Every recovered figure was verified against this file own prior cached values before recalculation; all 1,858 comparable numeric cells match to the cent, and all 41 active QA_Checks read PASS after a live LibreOffice recalculation.

Sheet 2024_Basis_Control
A1: 2024 Basis Control - Single-Year Inputs
A3: Input | B3: Value ($B) | C3: Use | D3: Source | E3: URL
A4: Personal income | B4: 24905.9 | C4: Individual tax; citizen-side SS | D4: FRED/BEA | E4: https://fred.stlouisfed.org/series/A065RC1A027NBEA
A5: Gross national income | B5: 28993.443 | C5: Guaranteed 5% citizen-side HSA credit | D5: World Bank/FRED | E5: https://fred.stlouisfed.org/series/MKTGNIUSA646NWDB
A6: Wages and salaries | B6: 11708.891 | C6: Employer SS, HSA, catastrophic pool | D6: FRED/BEA | E6: https://fred.stlouisfed.org/series/BA06RC1A027NBEA
A7: Corporate profits before tax | B7: 4179.16 | C7: Corporate tax base | D7: FRED/BEA | E7: https://fred.stlouisfed.org/series/A053RC1A027NBEA
A8: Federal receipts | B8: 4919 | C8: Current federal revenue | D8: CBO | E8: https://www.cbo.gov/publication/60843/html
A9: Federal outlays | B9: 6752 | C9: Current federal outlays | D9: CBO | E9: https://www.cbo.gov/publication/60843/html
A10: OASDI income | B10: 1418 | C10: Current SS income benchmark | D10: SSA | E10: https://www.ssa.gov/oact/TR/2025/III_A_cyoper.html
A11: OASDI cost | B11: 1485 | C11: SS cost target | D11: SSA | E11: https://www.ssa.gov/oact/TR/2025/III_A_cyoper.html
A12: National health expenditure | B12: 5300 | C12: Healthcare baseline | D12: CMS | E12: https://www.cms.gov/data-research/statistics-trends-and-reports/national-health-expenditure-data/nhe-fact-sheet
A13: Federal health sponsor pool | B13: 1643 | C13: NHDC catastrophic/public care fund | D13: CMS/NHE allocation | E13: https://www.cms.gov/data-research/statistics-trends-and-reports/national-health-expenditure-data/nhe-fact-sheet
A14: Employer government social-insurance contributions | B14: 866.444 | C14: Current employer burden | D14: FRED/BEA | E14: https://fred.stlouisfed.org/series/B039RC1A027NBEA
A15: Private business health sponsor pool | B15: 954 | C15: Current employer health burden | D15: CMS NHE | E15: https://www.cms.gov/data-research/statistics-trends-and-reports/national-health-expenditure-data/nhe-fact-sheet
... A24: FY2024 individual income tax receipts | B24: 2426 | C24: Current-system Before benchmark | D24: CBO/Treasury | E24: https://www.cbo.gov/publication/60843/html
A25: The statutory tax base is liquid personal income, defined in Liquid_Income_Base: wages and salaries, proprietors' income, monetary interest, monetary rental income, dividends, and realized capital gains, excluding government transfers, supplements to wages, and imputed (noncash) income. Headline BEA personal income is retained as a scale reference only and is no longer a tax base.
A26: Current-system comparators: FY2024 receipts $4,919B, outlays $6,752B, unified deficit -$1,833B; OASDI income $1,418B vs cost $1,485B = -$67B annual balance; corporate receipts about $530B; state/local property taxes $797B.
A28: Debt held by the public (end FY2024) | B28: 28200 | C28: Debt flywheel base | D28: US Treasury via FRED | E28: https://fred.stlouisfed.org/series/FYGFDPUN
A29: Net interest outlays (FY2024) | B29: 882 | C29: Interest expense baseline | D29: CBO/Treasury | E29: https://www.cbo.gov/publication/60843/html
A30: Effective average interest rate | B30: =B29/B28 -> 0.031276596 | C30: Derived: net interest / debt held by public | D30: Derived
A32: Proprietors' income (2024) | B32: 1970 | C32: Liquid base component | D32: BEA NIPA Table 2.1 / FRED PROPINC | E32: https://fred.stlouisfed.org/series/PROPINC
A33: Personal dividend income (2024) | B33: 1940 | C33: Liquid base component | D33: BEA NIPA Table 2.1 / FRED PDI | E33: https://fred.stlouisfed.org/series/PDI
A34: Personal interest income, monetary portion (2024) | B34: 1300 | C34: Liquid base component; excludes imputed interest | D34: BEA Table 2.1 / FRED PII, imputed removed [M] | E34: https://fred.stlouisfed.org/series/PII
A35: Rental income of persons, monetary portion (2024) | B35: 300 | C35: Liquid base component; excludes imputed owner-occupied rent | D35: BEA Table 2.1 monetary split [M] | E35: https://apps.bea.gov/iTable/?1903=58&1921=survey&reqid=19&step=3&isuri=1
A36: Equity compensation base (US public companies, latest FY) | B36: 366.7 | C36: Employer SS capital-wage base; equity surtax base | D36: Carver Edison SEC EDGAR dataset; MS Counterpoint $270B (2022) corroboration | E36: https://carveredison.com/research/stock-based-comp-report-2026/
A37: Vice sales base: alcohol+tobacco+gambling+cannabis (2024) | B37: 530 | C37: 5% sin sales surtax base | D37: Cannabis $30.1B Whitney Economics; alcohol/tobacco/gambling components [M], pin to industry sources | E37: https://cannabis.lacity.gov/articles/2024-us-cannabis-sales
A38: State/local government healthcare sponsor funding (2024) | B38: 848 | C38: Retained state/local healthcare funding | D38: CMS NHE sponsor share ~16% of NHE [M] | E38: https://www.cms.gov/data-research/statistics-trends-and-reports/national-health-expenditure-data/nhe-fact-sheet
A39: State/local employer-channel healthcare portion (2024) | B39: 190 | C39: Removed from sponsor funding to prevent double count | D39: 5%+5% of ~$1.9T state/local wages [M]
A40: State and local government wages (2024) | B40: 1900 | C40: State/local employer SS subcomponent display | D40: BEA govt compensation [M]
A41: Expanded liquid personal income base | B41: =Liquid_Income_Base!B16 -> 20470.758 | C41: Individual flat tax; citizen SS; citizen HSA tiers | D41: Liquid_Income_Base active total
A42: Retained current-law federal receipts | B42: 253 | C42: General Treasury receipts not replaced or repealed | D42: CBO FY2024 other receipts | E42: https://www.cbo.gov/publication/60843/html
A43: Policy source of truth | C43: Rates, bases, routing, and active mature-replacement treatment | D43: PolicyBook v86.0 plus approved corrections | E43: PolicyBook_v86_0.html
A44: Taxable IRA distributions | B44: 437.77558 | C44: Expanded liquid base | D44: IRS Publication 4801, TY2023 | E44: https://www.irs.gov/statistics/soi-tax-stats-individual-income-tax-returns-publication-1304-complete-report
A45: Taxable pensions and annuities | B45: 858.03834 | C45: Expanded liquid base | D45: IRS Publication 4801, TY2023 | E45: https://www.irs.gov/statistics/soi-tax-stats-individual-income-tax-returns-publication-1304-complete-report
A46: Estate and trust distributions | B46: 50.110198 | C46: Separate 3% tax base | D46: IRS Schedule E statistics | E46: https://www.irs.gov/statistics/soi-tax-stats-individual-income-tax-returns-publication-1304-complete-report
A47: Data-licensing payments to individuals | B47: 275 | C47: Expanded liquid base and corporate expense deduction | D47: Inherited active model base; direct 30% data tax removed
A48: Foreign cash income add-back | B48: 29.744257 | C48: Expanded liquid base | D48: IRS foreign earned income exclusion proxy | E48: https://www.irs.gov/statistics/soi-tax-stats-individual-income-tax-returns-publication-1304-complete-report

Sheet Liquid_Income_Base
A1: Liquid Personal Income Base - Expanded Active Tax Base
A2: One cash-availability definition governs the 10% individual tax, 3% citizen Social Security contribution, and 5% citizen-side HSA funding. Social Security and government assistance remain excluded. Data-licensing payments are income to the citizen rather than a separate data tax.
A3: Included component | B3: Active base ($B) | C3: 10% income tax ($B) | D3: 3% citizen SS ($B) | E3: 5% citizen-side HSA ($B) | F3: Source / treatment
A4: Wages and salaries | B4: =2024_Basis_Control!B6 -> 11708.891 | C4: =B4*10% -> 1170.8891 | D4: =B4*3% -> 351.26673 | E4: =B4*5% -> 585.44455 | F4: BEA/FRED BA06RC1A027NBEA
A5: Proprietors' and covered pass-through income | B5: =2024_Basis_Control!B32 -> 1970 | C5: =B5*10% -> 197 | D5: =B5*3% -> 59.1 | E5: =B5*5% -> 98.5 | F5: BEA/FRED PROPINC; partnership overlap controlled
A6: Personal dividend income | B6: =2024_Basis_Control!B33 -> 1940 | C6: =B6*10% -> 194 | D6: =B6*3% -> 58.2 | E6: =B6*5% -> 97 | F6: BEA/FRED PDI
A7: Personal interest income, monetary only | B7: =2024_Basis_Control!B34 -> 1300 | C7: =B7*10% -> 130 | D7: =B7*3% -> 39 | E7: =B7*5% -> 65 | F7: BEA/FRED PII less imputed interest
A8: Rental income excluding separately displayed royalties | B8: =2024_Basis_Control!B35-B9 -> 265.51241 | C8: =B8*10% -> 26.551241 | D8: =B8*3% -> 7.9653725 | E8: =B8*5% -> 13.275621 | F8: Existing $300B monetary rent/royalty line less IRS net royalties
A9: Royalties | B9: 34.487585 | C9: =B9*10% -> 3.4487585 | D9: =B9*3% -> 1.0346275 | E9: =B9*5% -> 1.7243792 | F9: IRS Schedule E net royalty income; explicitly included
A10: Realized capital gains | B10: =2024_Basis_Control!B20 -> 1600 | C10: =B10*10% -> 160 | D10: =B10*3% -> 48 | E10: =B10*5% -> 80 | F10: CBO central 2024 estimate
A11: Taxable IRA distributions | B11: 437.77558 | C11: =B11*10% -> 43.777558 | D11: =B11*3% -> 13.133267 | E11: =B11*5% -> 21.888779 | F11: IRS Publication 4801, Tax Year 2023
A12: Taxable pensions and annuities | B12: 858.03834 | C12: =B12*10% -> 85.803834 | D12: =B12*3% -> 25.74115 | E12: =B12*5% -> 42.901917 | F12: IRS Publication 4801, Tax Year 2023
A13: Legal settlements and other 1099-MISC cash income | B13: 51.308665 | C13: =B13*10% -> 5.1308665 | D13: =B13*3% -> 1.5392599 | E13: =B13*5% -> 2.5654332 | F13: IRS Publication 5385, Form 1099-MISC Box 3 proxy
A14: Foreign cash income currently excluded under federal rules | B14: 29.744257 | C14: =B14*10% -> 2.9744257 | D14: =B14*3% -> 0.89232771 | E14: =B14*5% -> 1.4872128 | F14: IRS Publication 4801, foreign earned income exclusion add-back
A15: Data-licensing payments to individuals | B15: 275 | C15: =B15*10% -> 27.5 | D15: =B15*3% -> 8.25 | E15: =B15*5% -> 13.75 | F15: Active model base inherited from prior $82.5B / 30% data-tax line; now routed as personal income
A16: Total active liquid personal income | B16: =SUM(B4:B15) -> 20470.758 | C16: =SUM(C4:C15) -> 2047.0758 | D16: =SUM(D4:D15) -> 614.12274 | E16: =SUM(E4:E15) -> 1023.5379 | F16: Full cash/liquid base before age and student micro-adjustments
A18: Separate Source-Level Taxes Outside the 10% Individual Liquid-Income Base
A19: Tax | B19: Active base ($B) | C19: Rate | D19: Revenue ($B) | E19: Reason for separate treatment | F19: Source / link
A20: Estate and trust distributions | B20: 50.110198 | C20: 0.03 | D20: =B20*C20 -> 1.5033059 | E20: User-approved 3% distribution levy rather than the 10% individual rate | F20: IRS Schedule E line 35 positive income
A21: Entity/transaction anti-deferral tax | B21: =Anti_Deferral_Tax!B9 -> 282.70996 | C21: 0.1 | D21: =Anti_Deferral_Tax!D9 -> 28.270996 | E21: Form 4797, like-kind deferred gain, REMIC and trade-up structures when no individual has received/solely owns the income | F21: Anti_Deferral_Tax
A23: Excluded from the liquid-income base
A24: Social Security benefits | E24: Explicitly excluded by policy
A25: Government benefits and public assistance | E25: Transfers rather than taxable earned/liquid income
A26: Return of previously taxed principal or basis | E26: Only economic income or gain is taxed
A27: Imputed interest, imputed owner-occupied rent, and other noncash accounting income | E27: Not available for the person to spend
A29: The 0% full-time-student wage treatment and 5% low-net-worth youth/elderly rate remain statutory. This national active model applies the headline 10% rate until taxpayer-level microdata can allocate those reduced rates without inventing a population split.

Sheet Tax_Revenue_2024
A1: 2024 Proposed Revenue — Fully Inclusive Studied Mature Replacement Model
A2: Every Policy Book revenue method is now included or explicitly shown at zero when deterrence-only. LVT remains unchanged by instruction. Dedicated receipts and public-enterprise earnings remain segregated from operating Treasury.
A3: Revenue line | B3: Basis | C3: Rate | D3: Amount ($B) | E3: Type | F3: Notes
A4: Individual income tax | B4: Expanded liquid personal income | C4: 0.1 | D4: =Liquid_Income_Base!C16 -> 2047.0758 | E4: General Treasury | F4: 10% on active liquid base; Social Security and public assistance excluded
A5: Corporate income tax central effective case | B5: Adjusted corporate profit base | C5: 0.1 | D5: =Corporate_Tax_Clear!E11 -> 390.416 | E5: General Treasury | F5: 15% statutory; active 10% effective Treasury rate after credits/deployment
A6: Estate and trust distribution tax | B6: Positive estate/trust distributions | C6: 0.03 | D6: =Liquid_Income_Base!D20 -> 1.5033059 | E6: General Treasury | F6: Separate 3% levy
A7: Entity/transaction anti-deferral tax | B7: Form 4797 + deferred like-kind + positive REMIC base | C7: 0.1 | D7: =Anti_Deferral_Tax!D9 -> 28.270996 | E7: General Treasury | F7: Source-level anti-loophole tax with individual-distribution credit
A8: Employer equity compensation surtax | B8: Equity compensation base, 9% aggregate | C8: 0.09 | D8: =Equity_Compensation!D19 -> 33.003 | E8: General Treasury | F8: Approved marginal schedule through $1M; upper tranche set at adoption
A9: Outsourcing Penalty | B9: Related-party manufacturing-import proxy | C9: 0.1 | D9: =Outsourcing_Penalty!D9 -> 142.92019 | E9: General Treasury | F9: Active proxy for companies outsourcing >50% of manufacturing
A10: Fair Profit Tax | B10: Original 2024 market screening study | D10: =Fair_Profit_Study!I16 -> 3.3070532 | E10: General Treasury | F10: PolicyBook calculator applied to qualifying mass-produced physical goods
A11: Loan Scumming taxes and fees | B11: Large-debt payoff plus 10-year audit recharacterization | D11: =Loan_Scumming!D14 -> 7.95 | E11: General Treasury | F11: 5% payoff tax plus retroactive 10% income tax
A12: Protectorate Fee | B12: 77-country legacy expenditure base | C12: 0.01 | D12: =Protectorate_Fee!F82 -> 151.4038 | E12: General Treasury | F12: 1% of covered government expenditure
A13: Flat Luxury Tax | B13: Qualified luxury-goods and luxury-asset sales | C13: 0.05 | D13: =Luxury_Tax!F10 -> 12.06373 | E13: General Treasury | F13: Flat 5% on the active Luxury_Tax market base
A14: Citizen Data Royalty | B14: Commercial monetization of U.S. citizen data | C14: 0.3 | D14: =Citizen_Data_Royalty!J13 -> 73.959598 | E14: Dedicated collection: Citizen Wealth Fund | F14: Collected by General Government; transferred in full to the CWF
A15: Sin sales surtax | B15: Alcohol, tobacco, gambling, marijuana sales | C15: 0.05 | D15: =2024_Basis_Control!B37*C15 -> 26.5 | E15: Earmarked: NHDC catastrophic | F15: Excluded from Treasury subtotal
A16: Federalized LVT | B16: Full federal land-rent capture target | D16: =2024_Basis_Control!B16 -> 2232.929 | E16: General Treasury | F16: Full $2.233T active scenario; primary residence exempt
A17: 1% national resource royalty | B17: Mining/extraction plus forestry | C17: 0.01 | D17: =Resource_Royalty!D6 -> 7.53102 | E17: General Treasury | F17: See Resource_Royalty
A18: Energy export excise | B18: Covered energy export sales | C18: 0.05 | D18: =Energy_Export_Excise!D12 -> 16.84285 | E18: General Treasury | F18: Active 5% deficit-year rate; returns to 4% after the prior-year consolidated budget is balanced
A19: Retained current-law federal receipts | B19: Receipt classes not replaced or repealed | D19: 253 | E19: General Treasury | F19: Customs, current excises, estate/gift receipts, fees, remittances, miscellaneous
A20: Idle Wealth Levy | B20: Certified concentrated nonproductive financial-reserve base | C20: 0.01 | D20: =Idle_Wealth_Levy!F13 -> 47.714505 | E20: General Treasury | F20: 1% excise; managers withhold for clients on covered managed assets; no cross-tier credit
A21: Offshore Capital Export Duty | B21: Covered passive outbound capital after U.S.-company expansion carveout | C21: 0.1 | D21: =Offshore_Capital_Duty!F12 -> 19.2 | E21: General Treasury | F21: 10% duty; central behavioral budget score
A22: High-Wealth Withholding and Compliance Recovery | B22: Existing unpaid liability collected at controlled intermediaries | D22: =High_Wealth_Compliance!F9 -> 38 | E22: General Treasury | F22: Collection mechanism; no new statutory tax rate
A23: Cross-policy overlap adjustment | B23: Overlap between offshore-duty and compliance-recovery channels | D23: -4 | E23: General Treasury | F23: Prevents double counting the same enforcement recovery
A24: Carbon Tax | B24: 2024 energy-related CO2 emissions × studied $25/t × 90% mature base | C24: 25 | D24: 107.4 | E24: General Treasury | F24: Studied rate and response; Policy Book rate was previously unspecified
A25: Spectrum stewardship: General Treasury share | B25: Auction, transfer, annual rent and vacancy fees | D25: 5 | E25: General Treasury | F25: Gross $12B; $6B to NIRF and $1B administration
A26: National laboratory patent marketplace | B26: Unified licensing and commercialization marketplace | D26: 0.4 | E26: General Treasury | F26: Net of $0.1B administration
A27: Federal Enterprise Data Services | B27: Enterprise subscriptions, processing and redistribution licenses | D27: 2 | E27: General Treasury | F27: Net of $1B operating cost
A28: Industrial campus leases and services | B28: Ground leases, utility contracts, testing, security and royalties | D28: 10 | E28: General Treasury | F28: Net of $5B campus operations
A29: Pipeline corridor capacity auctions | B29: National corridor capacity, ROW rents and auction fees | D29: 3.5 | E29: General Treasury | F29: Net of $0.5B administration
A30: Commercial space infrastructure | B30: Orbital, tracking, navigation and launch infrastructure services | D30: 3 | E30: General Treasury | F30: Net of $2B operations
A31: Patent troll penalties | B31: Covered abusive assertion penalties | D31: 0.5 | E31: General Treasury | F31: Small deterrence-based central estimate
A32: NIRF distributable investment return | B32: Mature protected corpus return under statutory transfer ceiling | D32: 150 | E32: General Treasury | F32: Studied $7.5T corpus, 4% real return, 50% transfer ceiling
A33: Unrestricted General Treasury subtotal | B33: All unrestricted external General revenue | D33: =SUM(D4:D13)+SUM(D16:D23)+SUM(D24:D32) -> 5710.9312 | E33: General Treasury | F33: Includes newly studied methods; excludes dedicated receipts
A34: Gross General-administered collections | B34: Treasury subtotal plus Citizen Data Royalty | D34: =D33+D14 -> 5784.8908 | E34: General administration | F34: Shows universal federal collection channel
A35: Citizen Wealth Fund transfer | B35: Equal to Citizen Data Royalty | D35: 73.959598 | E35: Dedicated outlay | F35: Full transfer; no ordinary Treasury availability
A36: NIRF capital receipt: spectrum share | B36: Spectrum auctions and rent allocation | D36: 6 | E36: Dedicated NIRF principal | F36: External receipt and protected asset purchase
A37: NHDC international license earnings | B37: International product and manufacturing licenses | D37: 12 | E37: Dedicated healthcare | F37: Separate from export margin
A38: NLA institutional/international earnings | B38: Institutional servicing and international lending | D38: 12 | E38: Dedicated Social Security | F38: Separate from domestic NLA distributable profit

Sheet Equity_Compensation
A1: Capital Wages - Employer Social Security Base Expansion and Employer Equity Compensation Surtax
A3: Line | B3: Basis | C3: Rate | D3: Amount ($B) | E3: Notes
A4: Equity compensation base | B4: US public companies, latest FY, SEC EDGAR aggregate | D4: =2024_Basis_Control!B36 -> 366.7 | E4: Carver Edison $366.7B across 1,680 issuers; Morgan Stanley Counterpoint ~$270B (2022) corroborates scale; private-company grants are upside
A5: Employer SS on cash wages | B5: Wages and salaries | C5: 0.03 | D5: =2024_Basis_Control!B6*C5 -> 351.26673 | E5: Unchanged 3% employer rate
A6: Employer SS on capital wages | B6: Equity compensation at fair value on transfer/vesting/settlement | C6: 0.03 | D6: =2024_Basis_Control!B36*C6 -> 11.001 | E6: Equity counted the same as cash; $5M grant owes $150K
A7: Total employer SS contribution | B7: Cash + capital wages | D7: =D5+D6 -> 362.26773 | E7: Carried into SS_Hybrid_2024
A8: State/local employer subcomponent (display) | B8: State/local government wages | C8: 0.03 | D8: =2024_Basis_Control!B40*C8 -> 57 | E8: Shown as a distinct line inside the national employer base; never additive
A10: Employer Equity Compensation Surtax - progressive, employer-paid, per employee per year
A11: Annual equity compensation per employee | B11: Marginal rate
A12: $1,000 or less | B12: 0
A13: Above $1,000 to $10,000 | B13: 0.05
A14: $10,000 to $100,000 | B14: 0.075
A15: $100,000 to $1,000,000 | B15: 0.1
A16: Above $1,000,000 | B16: Set at adoption
A18: Effective aggregate rate [M] | B18: 0.09 | E18: Active aggregate implementation rate across the documented equity-compensation base; upper statutory tranche remains set at adoption
A19: Surtax revenue | D19: =2024_Basis_Control!B36*B18 -> 33.003 | E19: Active General Treasury revenue line in Tax_Revenue_2024
A20: Three separated tax events remain active: employer Social Security on compensation value; employer equity surtax on the same value; and employee tax on later realized appreciation. Grants aggregate per employee per employer per tax period and apply marginally.

Sheet Corporate_Tax_Clear
A1: Corporate Tax - Gross Profit, Data-Licensing Deduction, and PolicyBook Rates
A3: Line | B3: Meaning | C3: Base ($B) | D3: Rate | E3: Treasury Revenue ($B) | F3: Non-Treasury Deployment ($B) | G3: Notes
A4: Gross corporate profit base | B4: 2024 profits before tax | C4: 4179.16 | G4: BEA corporate profits before tax
A5: Less: data-licensing payments to individuals | B5: Corporate expense transferred into personal liquid income | C5: 275 | G5: Avoids counting the same payment as corporate profit and personal income
A6: Adjusted corporate tax base | B6: Gross profit less modeled data-license payments | C6: =C4-C5 -> 3904.16 | G6: Active central base
A7: Current statutory CIT rate | B7: Legal rate, not collection | C7: =C4 -> 4179.16 | D7: 0.21 | G7: Current-law benchmark
A8: Current actual CIT receipts | B8: FY2024 actual federal receipts | E8: 530 | G8: Benchmark
A9: Current effective receipts rate | B9: Receipts / gross base | C9: =C4 -> 4179.16 | D9: =E8/C9 -> 0.12681974 | G9: Formula
A10: Proposed minimum direct tax | B10: 5% minimum paid after ordinary active reductions | C10: =C6 -> 3904.16 | D10: 0.05 | E10: =C10*D10 -> 195.208 | G10: PolicyBook minimum except qualifying real-investment exemption
A11: Proposed central effective Treasury tax | B11: 15% statutory rate after central active credits/deployment provisions | C11: =C6 -> 3904.16 | D11: 0.1 | E11: =C11*D11 -> 390.416 | G11: Active revenue bridge
A12: Proposed statutory rate before reductions | B12: PolicyBook v86 corporate rate | C12: =C6 -> 3904.16 | D12: 0.15 | E12: =C12*D12 -> 585.624 | G12: Ceiling before active credits
A13: Productive deployment channel | B13: Up to 5% reinvestment, bonuses, and covered support | C13: =C6 -> 3904.16 | D13: 0.05 | E13: 0 | F13: =C13*D13 -> 195.208 | G13: Not Treasury revenue

Sheet SS_Hybrid_2024
A1: Social Security - Expanded Liquid-Income Active Mature Replacement Year
A3: Line | B3: Basis | C3: Rate | D3: Amount ($B) | E3: Notes
A4: Current OASDI income | B4: SSA 2024 | D4: 1418 | E4: Benchmark
A5: Gross OASDI cost before payment-accuracy saving | B5: SSA 2024 gross cost | D5: 1485 | E5: Published gross benchmark; the dynamic path deducts the separately booked $6B payment-accuracy saving
A6: Citizen contribution | B6: 3% of expanded liquid personal income | C6: 0.03 | D6: =2024_Basis_Control!B41*C6 -> 614.12274 | E6: Uncapped; includes pensions, annuities, legal/misc cash, foreign cash, royalties, and data-licensing income
A7: Employer contribution | B7: 3% of all compensation: wages plus equity at fair value | C7: 0.03 | D7: =Equity_Compensation!D7 -> 362.26773 | E7: Capital wages covered; see Equity_Compensation
A8: of which: state/local government employers (display) | B8: 3% of state/local wages | C8: 0.03 | D8: =Equity_Compensation!D8 -> 57 | E8: Distinct subcomponent; already inside the wage base; never counted twice
A9: Hybrid SS subtotal | B9: Citizen + employer | D9: =D6+D7 -> 976.39047 | E9: Before NLA transfer
A10: Mature NLA profit transfer (baseline) | B10: Audited distributable NLA profit at mature scale | D10: =NLA_Model!E23 -> 154.13732 | E10: Mature replacement system is the headline baseline; initial/central are transition sensitivities
A11: Trust investment income (central) | B11: 50% CWF index / 50% diversified on reserves | D11: =SS_Trust_Investment!C12 -> 193.05 | E11: Income generated from protected $2.7T trust floor
A12: SS funding at mature baseline | B12: Hybrid + mature NLA + trust income | D12: =SUM(D9:D11) -> 1323.5778 | E12: Dedicated funding
A13: SS surplus/gap at mature baseline before RCN and payment accuracy | B13: Funding minus $1.485T gross cost | D13: =D12-D5 -> -161.42221 | E13: Gross-cost view; later tables show the $1.479T net obligation after the $6B dedicated payment-accuracy saving
A14: Noncitizen 7%/7% incremental contribution | B14: Noncitizen liquid income + employer compensation above baseline 3%/3% | D14: =Noncitizen_SS_Model!B17 -> 52.407964 | E14: See Noncitizen_SS_Model
A15: Noncitizen OASDI benefit exclusion saving | B15: Central modeled mature-year amount | D15: =Noncitizen_SS_Model!B21 -> 18 | E15: No benefits accrue while noncitizen
A16: Revised SS surplus/gap after citizen-only policy | B16: Funding plus savings less OASDI cost | D16: =D13+D14+D15 -> -91.014251 | E16: Before healthcare waterfall
A17: Central NLA year | B17: =NLA_Model!E22 -> 67.71298 | D17: =D9+B17+SS_Trust_Investment!C12-D5 -> -247.84655 | E17: Intermediate gap
A19: Gap-closure levers sit in Gap_Closure. Expanded income materially narrows the SS gap while preserving the adopted 3% citizen and 3% employer rates.

Sheet Gap_Closure
A1: Residual Funding Gaps - Offshore Duty and High-Wealth Recovery Added
A2: U.S.-company foreign operating expansion is carved out of the Offshore Capital Export Duty. Passive wealth export remains covered.
A3: Measure / lever | B3: Amount ($B) or rate | C3: Notes
A4: Pre-change consolidated replacement gap | B4: -28.759626 | C4: v23 baseline
A5: Energy Export Excise increase, 4% to 5% | B5: 3.36857 | C5: Automatic deficit-year setting
A6: Idle Wealth Levy, central case | B6: =Idle_Wealth_Levy!F13 -> 47.714505 | C6: 1% of direct and managed nonproductive financial-reserve bases
A7: Offshore Capital Export Duty | B7: =Offshore_Capital_Duty!F12 -> 19.2 | C7: Central score after full direct-investment expansion carveout
A8: High-Wealth withholding and compliance recovery | B8: =High_Wealth_Compliance!F9 -> 38 | C8: Existing liabilities collected earlier and more completely
A9: Cross-policy overlap adjustment | B9: -4 | C9: Prevents double counting
A10: Revised consolidated replacement balance | B10: =B4+B5+B6+B7+B8+B9 -> 75.523448 | C10: Positive = recurring surplus
A11: Revised General Government balance before SS support | B11: =Deficit_Views!B43 -> 318.95606 | C11: Healthcare and SS ledgers unchanged
A12: Social Security dedicated gap | B12: =Deficit_Views!B45 -> 0 | C12: Still visible as a dedicated-ledger gap
A13: Healthcare dedicated reserve | B13: =Deficit_Views!B44 -> 376.50949 | C13: Still retained in Healthcare
A14: Previous v25 consolidated balance
A15: Current-system unified federal balance | B15: -1833 | C15: FY2024 benchmark
A16: Further reserve mechanisms | B16: 0 | C16: NIRF and spectrum revenue remain unbooked until fiscal valuation is completed

Sheet SS_Trust_Investment
A1: Social Security Trust Investment - Protected $2.7T Floor | 50% Citizen Wealth Fund Index / 50% Diversified
A3: Line | B3: Basis | C3: Rate/Share | D3: Amount ($B) | E3: Notes
A4: OASDI asset reserves (end 2024) | B4: SSA 2025 Trustees Report | D4: 2700 | E4: Statutory minimum corpus protected by Treasury backstop
A5: CWF index sleeve share | B5: Statutory allocation | C5: 0.5 | D5: =D4*C5 -> 1350 | E5: 50% in Citizen Wealth Fund index
A6: Diversified sleeve share | B6: Bonds/hard reserves/stable holdings | C6: 0.5 | D6: =D4*C6 -> 1350 | E6: Remaining 50%
A7: CWF index long-run nominal return (central) | B7: US equity total return 1928-2024 | C7: 0.099 | E7: Damodaran/NYU historical returns
A8: Diversified sleeve yield (central) | B8: 10-year Treasury, 2024 average | C8: 0.044 | E8: FRED DGS10
A10: Scenario | B10: Blended yield | C10: Trust investment income ($B) | D10: Assumption
A11: Conservative | B11: =(0.08+0.044)/2 -> 0.062 | C11: =D4*B11 -> 167.4 | D11: Equity sleeve at 8.0%
A12: Central | B12: =(C7+C8)/2 -> 0.0715 | C12: =D4*B12 -> 193.05 | D12: Equity at 9.9%, bonds at 4.4%
A13: Optimistic | B13: =(0.11+0.044)/2 -> 0.077 | C13: =D4*B13 -> 207.9 | D13: Equity sleeve at 11.0%
A15: Current-law comparison
A16: Special-issue effective rate (approx.) | B16: 0.025 | C16: =D4*B16 -> 67.5 | D16: SSA trust fund interest rates
A17: Incremental income, central vs current | C17: =C12-C16 -> 125.55 | D17: Yield gained by investing the trust
A19: The allocation is fixed in statute at 50% Citizen Wealth Fund index and 50% diversified holdings, rebalanced on schedule and published in full at every audit. Returns are long-run nominal averages; single-year sequence-of-returns risk requires the diversified sleeve and reserve discipline during the transition. Central income is carried into the Social Security funding bridge.

Sheet Healthcare_3_5_5
A1: Healthcare - Expanded Liquid-Income Active Mature Replacement Year
A3: Line | B3: Basis | C3: Rate | D3: Amount ($B) | E3: Layer | F3: Notes
A4: Current healthcare baseline | B4: CMS 2024 NHE | D4: 5300 | E4: Current cost | F4: Gross-price current system
A5: Conservative structural savings | B5: 20% cost reduction | C5: -0.2 | D5: =D4*C5 -> -1060 | E5: Cost reduction | F5: Conservative floor
A6: Proposed cost target at 20% savings | B6: NHE less savings | D6: =D4+D5 -> 4240 | E6: Cost target | F6: Funding target
A7: Citizen-paid HSA | B7: Tiered 2/3/5% on liquid personal income | D7: =2024_Basis_Control!B41*0.05*0.72527 -> 742.34133 | E7: HSA basic care | F7: Tier mix share 72.527% retained from v18 [M]; expanded liquid-income base applies
A8: Federal HSA supplement | B8: Top-up to the 5% citizen-side credit on liquid income | D8: =2024_Basis_Control!B41*0.05-D7 -> 281.19657 | E8: HSA basic care | F8: Federal top-up to maintain the full 5% citizen-side HSA funding floor
A9: Employer HSA match | B9: 5% of wages | C9: 0.05 | D9: =2024_Basis_Control!B6*C9 -> 585.44455 | E9: HSA basic care | F9: Portable worker-owned HSA
A10: Total HSA basic/direct care pool | B10: Citizen + federal + employer | D10: =SUM(D7:D9) -> 1608.9824 | E10: HSA basic care | F10: Routine/direct care
A11: Federal health sponsor pool | B11: Redirected current federal health pool | D11: =2024_Basis_Control!B13 -> 1643 | E11: NHDC catastrophic/public | F11: Transfer from the General Government silo
A12: State/local governmental healthcare funding | B12: Retained sponsor funding net of employer channels | D12: =2024_Basis_Control!B38-2024_Basis_Control!B39 -> 658 | E12: NHDC catastrophic/public | F12: Shift: state/local funding is retained in the national floor; employer-channel dollars removed to prevent double count
A13: NHDC domestic operating margin | B13: Domestic manufacturing under the three-times-cost ceiling | D13: 100 | E13: Internal operating result | F13: Retained inside the healthcare system but excluded from external funding to avoid double counting patient payments
A14: NHDC International Exports margin | B14: Mature export scenario (baseline) | D14: =NHDC_Exports!D10 -> 82.5825 | E14: External healthcare funding | F14: Foreign customer funds the domestic mission; see NHDC_Exports
A15: Public hospital operating surplus | B15: Public hospital operating result | D15: 13 | E15: Internal operating result | F15: Retained for operations and improvements but excluded from external funding
A16: Sin sales surtax earmark | B16: 5% of vice sales (§2) | C16: 0.05 | D16: =2024_Basis_Control!B37*C16 -> 26.5 | E16: NHDC catastrophic/public | F16: Statutory routing; excluded from Treasury
A17: External catastrophic/public-care funding | B17: Federal sponsor + state/local + exports + sin surtax | D17: =SUM(D11:D12)+D14+D16 -> 2410.0825 | E17: NHDC catastrophic/public | F17: Excludes domestic NHDC margin and public-hospital surplus
A18: Employer Catastrophic Care-Pool contribution | B18: 5% of wages | C18: 0.05 | D18: =2024_Basis_Control!B6*C18 -> 585.44455 | E18: Catastrophic pool | F18: Restricted national care pool
A19: Total external healthcare funding | B19: HSA + external catastrophic/public + employer pool | D19: =D10+D17+D18 -> 4604.5095 | E19: All layers | F19: No internal provider margin counted as new funding
A20: Healthcare reserve/gap at 20% savings | B20: Funding - cost target | D20: =D19-D6 -> 364.50949 | E20: Result | F20: Positive = reserve
A21: Central 22% savings target | B21: NHE less 22% | C21: -0.22 | D21: =D4*(1+C21) -> 4134 | E21: Sensitivity | F21: Reference central estimate
A22: Reserve/gap at 22% | B22: Funding - 22% target | D22: =D19-D21 -> 470.50949 | E22: Sensitivity | F22: Positive = reserve
A23: Internal retained operating margins | B23: NHDC domestic margin + public-hospital surplus | D23: =D13+D15 -> 113 | E23: Memo only | F23: Shown for transparency; excluded from funding and consolidated revenue
A24: State supplements above the national floor are state-funded and remain outside this national average-year breakeven. Transition costs, capital build-out, and unrelated general policies are not included in this replacement baseline.

Sheet NHDC_Exports
A1: NHDC International Exports - Three-Times-Cost Ceiling for the Citizen, At Market for the World
A3: Line | B3: Basis | C3: Share/Margin | D3: Amount ($B) | E3: Notes
A4: Global generic pharmaceuticals market (2024) | B4: Statista / Grand View | D4: =2024_Basis_Control!B22 -> 455 | E4: Addressable export market
A5: Net export margin assumption | B5: Public producer under a domestic three-times-cost ceiling selling abroad at market prices; no marketing or shareholder cost | C5: 0.55 | E5: Scenario assumption; documented, not sourced
A7: Scenario | B7: Global share | C7: Export revenue ($B) | D7: Net margin to catastrophic fund ($B)
A8: Initial | B8: 0.05 | C8: =D4*B8 -> 22.75 | D8: =C8*$C$5 -> 12.5125
A9: Central | B9: 0.2 | C9: =D4*B9 -> 91 | D9: =C9*$C$5 -> 50.05
A10: Mature | B10: 0.33 | C10: =D4*B10 -> 150.15 | D10: =C10*$C$5 -> 82.5825
A12: Every dollar of export margin routes to the domestic mission: the catastrophic care fund, safety-net hospitals, and expanded manufacturing capacity. The central scenario (20% global share) reflects a state manufacturer with US regulatory standing undercutting global generic cartels; India today supplies roughly 40% of US generic volume, so large single-nation shares are precedented. Domestic essential generics sell under a statutory price ceiling of three times cost (maximum 200% margin), with the headroom retiring research and development cost; domestic profit remains inside the Healthcare silo and is never Treasury revenue. The mature scenario is the replacement-budget baseline.

Sheet Employer_Burden
A1: Employer Burden - Current Benchmark vs Proposed 3+5+5
A3: Line | B3: Current ($B) | C3: Proposed ($B) | D3: Formula/Basis | E3: % Payroll | F3: Notes
A4: Employer gov social-insurance contributions | B4: 866.444 | D4: Current FRED benchmark | E4: =B4/2024_Basis_Control!B6 -> 0.07399881 | F4: Current
A5: Private business health sponsor pool | B5: 954 | D5: CMS private business health sponsor pool | E5: =B5/2024_Basis_Control!B6 -> 0.081476546 | F5: Current
A6: Current employer burden benchmark | B6: =SUM(B4:B5) -> 1820.444 | D6: Current social + health | E6: =B6/2024_Basis_Control!B6 -> 0.15547536 | F6: Broad benchmark
A7: Social Security employer match | C7: =2024_Basis_Control!B6*3% -> 351.26673 | D7: 3% wages | E7: =C7/2024_Basis_Control!B6 -> 0.03 | F7: Payroll-based
A8: Portable HSA match | C8: =2024_Basis_Control!B6*5% -> 585.44455 | D8: 5% wages | E8: =C8/2024_Basis_Control!B6 -> 0.05 | F8: Minimum; employers can offer more
A9: Catastrophic Care-Pool contribution | C9: =2024_Basis_Control!B6*5% -> 585.44455 | D9: 5% wages | E9: =C9/2024_Basis_Control!B6 -> 0.05 | F9: National pool
A10: Proposed employer burden | C10: =SUM(C7:C9) -> 1522.1558 | D10: 13% payroll | E10: =C10/2024_Basis_Control!B6 -> 0.13 | F10: Stable payroll-based
A11: Employer burden reduction / increase | C11: =B6-C10 -> 298.28817 | D11: Current - proposed | E11: =C11/2024_Basis_Control!B6 -> 0.025475356 | F11: Positive = savings
A12: Small-business relief/credit pool | C12: 10 | D12: General-budget surge reserve | F12: Transition relief plus national-lockdown/disaster surge fund; the reserve also serves as the administrative chassis for emergency appropriations, so $10B is standing capacity and the pipe, not the ceiling.

Sheet LVT_External_Validation
A1: External LVT Validation - Federalized Land-Rent Capture by Land Type
A3: Land / benchmark type | B3: External value | C3: Units | D3: Illustrative treatment | E3: Illustrative rate | F3: Potential revenue ($B) | G3: Source | H3: Validation limitation
A4: Current state/local property-tax collections | B4: 797 | C4: $B | D4: Replacement benchmark | G4: https://eyeonhousing.org/tag/state-and-local-tax-revenue/ | H4: Includes improvements as well as land; benchmark only.
A5: U.S. farm real estate | B5: 4170 | C5: $/acre | D5: Agricultural reference | E5: 0.01 | G5: https://www.nass.usda.gov/Publications/Todays_Reports/reports/land0824.pdf | H5: Farm real estate includes land and buildings.
A6: U.S. cropland | B6: 5570 | C6: $/acre | D6: Lower-rate productive land | E6: 0.01 | G6: https://www.nass.usda.gov/Publications/Todays_Reports/reports/land0824.pdf | H6: Per-acre national average; acreage/appraisal needed.
A7: U.S. pasture | B7: 1830 | C7: $/acre | D7: Lower-rate grazing land | E7: 0.005 | G7: https://www.nass.usda.gov/Publications/Todays_Reports/reports/land0824.pdf | H7: Per-acre national average; acreage/appraisal needed.
A8: Household/nonprofit real estate | B8: 52987.317 | C8: $B | D8: Residential scale anchor; primary homes exempt operationally | G8: https://fred.stlouisfed.org/series/HNOREMV | H8: Land and structures combined; Q1 2026 scale anchor, not taxable base.
A9: Nonfinancial corporate real estate | B9: 15694.221 | C9: $B | D9: Commercial/industrial scale anchor | G9: https://fred.stlouisfed.org/series/BOGZ1LM105035005A | H9: Land and structures combined.
A10: Noncorporate business real estate | B10: 17463.06 | C10: $B | D10: Rental/commercial scale anchor | G10: https://fred.stlouisfed.org/series/NNCBIRER | H10: Land and structures combined; Q1 2026 scale anchor.
A11: Vacant/speculative urban land | B11: Parcel appraisal required | C11: - | D11: Higher capture rate | G11: Local assessment rolls / federal parcel model | H11: No national land-only total presently used.
A12: Second homes / non-primary residential land | B12: Parcel appraisal required | C12: - | D12: Residential LVT applies | G12: County assessment records / federal parcel model | H12: Primary residence exemption must be separated parcel by parcel.
A13: Mineral rights / extraction lease value | B13: Royalty model separate | C13: - | D13: Avoid double counting with resource royalty | G13: Federal/state lease records | H13: LVT applies to location rent; extraction royalty applies to removed resource.
A15: Model target reconciliation | B15: Amount ($B) | C15: Formula / status
A16: Current property-tax replacement benchmark | B16: 797 | C16: Externally benchmarked
A17: Federalized LVT target | B17: 2232.929 | C17: Policy target pending parcel-level validation
A18: Additional federal land-rent capture | B18: =B17-B16 -> 1435.929 | C18: Target less current benchmark
A19: LVT scale ratio | B19: =B17/B16 -> 2.8016675 | C19: Target / property-tax benchmark
A21: The LVT target is retained as a policy scenario, not represented as fully proven. A national parcel-level model must separate land from improvements, primary residences from taxable residential land, and productive agricultural land from speculative or high-rent urban land.
A22: IMPLIED CAPTURE RATE AGAINST THE FEDERAL RESERVE REAL-ESTATE ENVELOPE
A23: Measure | B23: Value | C23: Unit | D23: Formula | E23: Interpretation | F23: Source | G23: Status | H23: Limitation
A24: Combined Fed real-estate envelope | B24: =SUM(B8:B10) -> 86144.598 | C24: $B | D24: Household/nonprofit + corporate + noncorporate real estate | E24: Broad upper envelope that includes structures | F24: Federal Reserve/FRED series listed above | G24: External | H24: Not land-only
A25: Federalized LVT target | B25: =B17 -> 2232.929 | C25: $B | D25: Active policy target | E25: Booked revenue | F25: Policy model | G25: Adopted | H25: Pending parcel validation
A26: Target / full real-estate envelope | B26: =B25/B24 -> 0.025920708 | C26: Annual share | D26: LVT target divided by land-and-structures envelope | E26: Lower-bound implied capture rate because structures and exempt primary homes remain in the denominator | F26: Calculated | G26: Calculated | H26: True taxable-land rate will be higher
A27: Illustrative taxable land-only base | B27: =B24*40%*50% -> 17228.92 | C27: $B | D27: 40% land share × 50% taxable share after exemptions | E27: Central disclosure scenario, not a parcel estimate | F27: Model disclosure assumption | G27: Illustrative | H27: Actual land and exemption shares require parcel data
A28: Implied rate on illustrative taxable land-only base | B28: =B25/B27 -> 0.12960354 | C28: Annual share | D28: LVT target divided by illustrative taxable land-only base | E28: Shows the parcel study must validate a materially higher land-only rate | F28: Calculated | G28: Calculated | H28: Sensitivity, not legal validation
A30: Land share | B30: Taxable share after exemptions | C30: Taxable land base ($B) | D30: Implied annual LVT rate | E30: Interpretation
A31: 0.3 | B31: 0.35 | C31: =$B$24*A31*B31 -> 9045.1828 | D31: =$B$25/C31 -> 0.24686389 | E31: Illustrative sensitivity; parcel model required
A32: 0.3 | B32: 0.5 | C32: =$B$24*A32*B32 -> 12921.69 | D32: =$B$25/C32 -> 0.17280472 | E32: Illustrative sensitivity; parcel model required
A33: 0.3 | B33: 0.65 | C33: =$B$24*A33*B33 -> 16798.197 | D33: =$B$25/C33 -> 0.13292671 | E33: Illustrative sensitivity; parcel model required
A34: 0.4 | B34: 0.35 | C34: =$B$24*A34*B34 -> 12060.244 | D34: =$B$25/C34 -> 0.18514792 | E34: Illustrative sensitivity; parcel model required
A35: 0.4 | B35: 0.5 | C35: =$B$24*A35*B35 -> 17228.92 | D35: =$B$25/C35 -> 0.12960354 | E35: Illustrative sensitivity; parcel model required
A36: 0.4 | B36: 0.65 | C36: =$B$24*A36*B36 -> 22397.595 | D36: =$B$25/C36 -> 0.099695032 | E36: Illustrative sensitivity; parcel model required
A37: 0.5 | B37: 0.35 | C37: =$B$24*A37*B37 -> 15075.305 | D37: =$B$25/C37 -> 0.14811833 | E37: Illustrative sensitivity; parcel model required
A38: 0.5 | B38: 0.5 | C38: =$B$24*A38*B38 -> 21536.149 | D38: =$B$25/C38 -> 0.10368283 | E38: Illustrative sensitivity; parcel model required
A39: 0.5 | B39: 0.65 | C39: =$B$24*A39*B39 -> 27996.994 | D39: =$B$25/C39 -> 0.079756026 | E39: Illustrative sensitivity; parcel model required

Sheet Resource_Royalty
A1: 1% National Resource Royalty - Extraction from U.S. Soil
A3: Covered scope | B3: 2024 base ($B) | C3: Rate | D3: Revenue ($B) | E3: Model status | F3: Notes | G3: Source
A4: Mining, quarrying, oil and gas extraction | B4: 706.4 | C4: 0.01 | D4: =B4*C4 -> 7.064 | E4: Core | F4: Covers oil, natural gas, coal, rare earths, precious/base metals, industrial minerals, quarrying, uranium, and peat where captured in NAICS 21 gross output. | G4: https://fred.stlouisfed.org/series/GOM
A5: Forestry and logging proxy | B5: 46.702 | C5: 0.01 | D5: =B5*C5 -> 0.46702 | E5: Conservative proxy | F5: Uses 2024 real GDP for forestry, fishing and related activities because a clean national forestry-only gross-output series was not available in the model. Replace with BEA forestry/logging gross receipts when available. | G5: https://fred.stlouisfed.org/series/USFRSTFISHRGSP
A6: Core royalty including forestry | B6: =SUM(B4:B5) -> 753.102 | D6: =SUM(D4:D5) -> 7.53102
A8: The royalty is assessed on gross extraction sales/output before downstream refining or manufacturing. Small-producer relief may be appropriated separately, but the royalty itself remains a national return on removed natural wealth.

Sheet Deficit_Views
A1: Expanded Revenue, Cost Discipline, Resident Contributor, and National Continuity Budget - Average Mature Year (v32)
A2: Adds the Offshore Capital Export Duty with a full U.S.-company foreign-expansion carveout, plus High-Wealth Withholding and Compliance Recovery.
A3: TABLE 0 - OLD MODEL BENCHMARK (FY2024)
A4: Line | B4: Amount ($B) | C4: Notes
A5: Current federal receipts | B5: =2024_Basis_Control!B8 -> 4919 | C5: Unified federal benchmark
A6: Current federal outlays | B6: =2024_Basis_Control!B9 -> 6752 | C6: Unified federal benchmark
A7: Current unified federal balance | B7: =B5-B6 -> -1833 | C7: Receipts less outlays
A8: Current OASDI income | B8: =2024_Basis_Control!B10 -> 1418 | C8: Includes current-law trust interest
A9: Current OASDI cost | B9: =2024_Basis_Control!B11 -> 1485 | C9: Annual obligation
A10: Current OASDI balance | B10: =B8-B9 -> -67 | C10: Income less cost
A11: Current national health expenditure | B11: =2024_Basis_Control!B12 -> 5300 | C11: National cost benchmark
A13: TABLE 1 - GENERAL GOVERNMENT FUNDING
A14: Line | B14: Amount ($B) | C14: Notes
A15: Unrestricted General Treasury revenue | B15: =Tax_Revenue_2024!D24 -> 107.4 | C15: Excludes dedicated Citizen Data Royalty
A16: Citizen Data Royalty collection | B16: =Tax_Revenue_2024!D14 -> 73.959598 | C16: Externally collected through General Government
A17: Gross General-administered revenue | B17: =B15+B16 -> 181.3596 | C17: Treasury plus dedicated royalty
A18: Ordinary federal outlays | B18: =2024_Basis_Control!B9-2024_Basis_Control!B11-2024_Basis_Control!B13-Cost_Savings_Program!B27 -> 3460 | C18: FY2024 ordinary outlays less OASDI, current federal healthcare, and $164B mature-year cost savings
A19: Federal health sponsor transfer | B19: =2024_Basis_Control!B13 -> 1643 | C19: Internal transfer into Healthcare ledger
A20: Federal HSA supplement | B20: =Healthcare_3_5_5!D8 -> 281.19657 | C20: Internal transfer into Healthcare ledger
A21: Citizen Wealth Fund transfer | B21: =B16 -> 73.959598 | C21: Equal to Citizen Data Royalty collection
A22: Small Business Surge Reserve | B22: 10 | C22: Standing General Government reserve active in ordinary years
A23: General Government balance before SS support | B23: =B17-SUM(B18:B22) -> -5286.7966
A24: Potential Treasury transfer to close SS gap | B24: =MAX(0,-SS_Hybrid_2024!D13) -> 161.42221 | C24: Memo only; not included in row 23
A26: TABLE 2 - NATIONAL HEALTHCARE FUNDING
A27: Line | B27: Amount ($B) | C27: Notes
A28: Total external healthcare funding | B28: =Healthcare_3_5_5!D19 -> 4604.5095 | C28: Includes federal internal transfers on this ledger
A29: National health expenditure at 20% savings | B29: =Healthcare_3_5_5!D6 -> 4240 | C29: Average mature-year cost target
A30: Healthcare balance | B30: =B28-B29 -> 364.50949 | C30: Positive = dedicated reserve
A31: Internal NHDC/public-hospital margins
A32: Optional state supplements and transition capital | B32: 0 | C32: Outside the national breakeven
A34: TABLE 3 - SOCIAL SECURITY FUNDING
A35: Line | B35: Amount ($B) | C35: Notes
A36: Total dedicated SS funding | B36: =SS_Hybrid_2024!D12+SS_Hybrid_2024!D14+12+National_Continuity!B24 -> 1593.6655 | C36: Citizen + employer + mature NLA + protected trust return + RCN increment + NCC amount needed for breakeven
A37: OASDI cost target | B37: =SS_Hybrid_2024!D5-SS_Hybrid_2024!D15-6 -> 1461 | C37: Annual obligation
A38: Social Security balance | B38: =B36-B37 -> 132.66554
A39: General support can close row 38 without changing the consolidated result.
A41: TABLE 4 - CONSOLIDATED REPLACEMENT RESULT
A42: Line | B42: Amount ($B) | C42: Notes
A43: General Government balance | B43: =37.1560610633821+(Tax_Revenue_2024!D33-5429.13123619) -> 318.95606 | C43: General Government balance including federal SSI savings; before any residual SS backstop
A44: Healthcare balance | B44: =364.50949205+12 -> 376.50949 | C44: Healthcare is independent; reserve and residual public-capital allocations remain within its ledger
...

Sheet Reclassified_Outlays
A1: Consolidated Reconciliation | Year 10 Mature Budget
A2: The reconciliation sums each ledger balance and each external protected-capital receipt once. Internal transfers are excluded.
A3: Line | B3: Amount ($B) | C3: Treatment
A4: General Government balance | B4: =Deficit_Views!B43 -> 318.95606 | C4: External General Government ledger result
A5: Healthcare balance | B5: =Deficit_Views!B44 -> 376.50949 | C5: Independent healthcare ledger result
A6: Social Security ending balance | B6: =Deficit_Views!B45 -> 0 | C6: After Resident Contributor receipts and NCC transfer
A7: NCC residual to NIRF | B7: =National_Continuity!D26 -> 378.06546 | C7: External NCC revenue retained as protected NIRF principal
A8: Spectrum NIRF capital receipt | B8: =6 -> 6 | C8: External spectrum receipt retained as protected NIRF principal
A9: Calculated consolidated replacement balance | B9: =SUM(B4:B8) -> 1079.531 | C9: No internal transfer counted twice
A10: Published consolidated replacement balance | B10: =Deficit_Views!B46 -> 1079.531 | C10: Headline result
A11: Must equal zero | B11: =B9-B10 -> 0 | C11: Publication control

Sheet Debt_Flywheel
A1: Deferred Module - Debt Flywheel (v21)
A2: Not included in the average mature replacement-year headline.
A4: Reason deferred | B4: The funding model must first close its annual consolidated gap before debt retirement or interest-savings feedback can be modeled as a benefit.
A5: Current headline balance | B5: =Deficit_Views!B43 -> 318.95606
A6: Status | B6: Deferred until the base funding gap is closed
A8: This worksheet is retained for the later multi-year model. It contributes zero to the v21 active average-year headline.

Sheet Post_Term_Results
A1: Deferred Module - Multi-Year and Post-Term Results (v21)
A2: Not included in the average mature replacement-year headline.
A4: Measure | B4: Value | C4: Status | D4: Notes
A5: Annual consolidated replacement balance | B5: =Deficit_Views!B43 -> 318.95606 | C5: Active baseline | D5: Links to Deficit_Views
A6: Debt trajectory | B6: 0 | C6: Deferred | D6: Requires a closed annual gap and explicit borrowing assumptions
A7: Interest flywheel | B7: 0 | C7: Deferred | D7: Not credited to the headline
A8: Transition costs | B8: 0 | C8: Out of scope | D8: Average mature-year model only
A9: General Policy Book initiatives | B9: 0 | C9: Out of scope | D9: Costed later
A11: This sheet prevents multi-year effects from being confused with the steady-state replacement comparison.

Sheet Replacement_Summary
A1: Current System to Fully Inclusive Studied Mature Replacement Year - v34
A2: All Policy Book revenue methods are now included in the budget summary. Former placeholders have studied central estimates with ranges and sources. LVT is unchanged.
A4: Metric | B4: Old model / FY2024 benchmark ($B) | C4: New replacement model ($B) | D4: Change ($B) | E4: Interpretation | F4: Scope note
A5: Federal / General Government balance | B5: -1833 | C5: =Deficit_Views!B43 -> 318.95606 | D5: =C5-B5 -> 2151.9561 | E5: General Government balance before any residual Social Security backstop | F5: Citizen Data Royalty collection and CWF transfer net to zero
A6: Social Security annual balance | B6: -67 | C6: =Deficit_Views!B45 -> 0 | D6: =C6-B6 -> 67 | E6: Social Security ending balance after Resident Contributor and NCC funding | F6: Mature NLA and trust assumptions unchanged
A7: National healthcare annual cost | B7: 5300 | C7: =Healthcare_3_5_5!D6 -> 4240 | D7: =C7-B7 -> -1060 | E7: 20% modeled structural savings | F7: Cost rather than budget balance
A8: Healthcare dedicated balance | B8: 0 | C8: =Deficit_Views!B44 -> 376.50949 | D8: =C8-B8 -> 376.50949 | E8: Independent healthcare ledger balance including international licensing | F8: Internal provider margins excluded
A9: Consolidated replacement balance | B9: -1833 | C9: =Deficit_Views!B46 -> 1079.531 | D9: =C9-B9 -> 2912.531 | E9: System-wide recurring result | F9: All scoped active mechanisms included
A11: Headline Inputs and Outputs
A12: Expanded liquid personal income base | C12: =Liquid_Income_Base!B16 -> 20470.758 | E12: Income taxed once when liquid/available
A13: Unrestricted General Treasury revenue | C13: =Tax_Revenue_2024!D33 -> 5710.9312 | E13: Available for ordinary General Government operations
A14: Citizen Data Royalty collection | C14: =Tax_Revenue_2024!D14 -> 73.959598 | E14: Dedicated external collection
A15: Citizen Wealth Fund transfer | C15: =-Tax_Revenue_2024!D35 -> -73.959598 | E15: Equal dedicated transfer to Citizen Wealth Fund
A16: Gross General-administered collections | C16: =Tax_Revenue_2024!D34 -> 5784.8908 | E16: Operating Treasury plus Citizen Data Royalty collection
A17: Luxury Tax revenue | C17: =Tax_Revenue_2024!D13 -> 12.06373 | E17: Flat 5% General Treasury revenue
A18: General Government balance | C18: =Deficit_Views!B43 -> 318.95606 | E18: Before SS support
A19: Healthcare balance | C19: =Deficit_Views!B44 -> 376.50949 | E19: Independent healthcare ledger balance
A20: Social Security balance | C20: =Deficit_Views!B45 -> 0 | E20: Balanced after dedicated funding and NCC transfer
A21: Consolidated replacement balance
A23: Active Policy Inputs in the Headline
A24: Individual income tax | B24: 10% expanded liquid base | C24: =Tax_Revenue_2024!D4 -> 2047.0758 | D24: ACTIVE | E24: Pensions, annuities, royalties, legal/misc cash, foreign cash, data licensing
A25: Estate and trust distribution tax | B25: 3% | C25: =Tax_Revenue_2024!D6 -> 1.5033059 | D25: ACTIVE | E25: Positive distributions
A26: Entity/transaction anti-deferral tax | B26: 10% | C26: =Tax_Revenue_2024!D7 -> 28.270996 | D26: ACTIVE | E26: Form 4797, deferred like-kind gain, positive REMIC
A27: Outsourcing Penalty | B27: 10% | C27: =Tax_Revenue_2024!D9 -> 142.92019 | D27: ACTIVE | E27: Related-party manufacturing-import proxy for >50% outsourcing
A28: Fair Profit Tax | B28: PolicyBook calculator | C28: =Tax_Revenue_2024!D10 -> 3.3070532 | D28: ACTIVE | E28: Original 2024 market screening study
A29: Loan Scumming taxes | B29: 5% payoff + 10% audit | C29: =Tax_Revenue_2024!D11 -> 7.95 | D29: ACTIVE | E29: Asset-backed borrowing used to avoid realization
A30: Protectorate Fee | B30: 1% | C30: =Tax_Revenue_2024!D12 -> 151.4038 | D30: ACTIVE | E30: 77-country legacy expenditure base
A31: Flat Luxury Tax | B31: 5% | C31: =Tax_Revenue_2024!D13 -> 12.06373 | D31: ACTIVE | E31: Personal luxury goods, luxury vehicles, yachts, and business jets
A32: Citizen Data Royalty | B32: 30% | C32: =Tax_Revenue_2024!D14 -> 73.959598 | D32: ACTIVE / CWF | E32: Data-market base with overlap deductions
A33: Federalized Land Value Tax | B33: Full scenario | C33: =Tax_Revenue_2024!D16 -> 2232.929 | D33: ACTIVE | E33: Primary home exempt; full revenue booked
A34: Retained current-law federal receipts | B34: Aggregate | C34: =Tax_Revenue_2024!D19 -> 253 | D34: ACTIVE | E34: Receipt classes not repealed
A35: Energy export excise | B35: 5% deficit-year | C35: =Tax_Revenue_2024!D18 -> 16.84285 | D35: ACTIVE | E35: Automatic 5% when prior-year consolidated balance is negative
A36: Employer equity compensation surtax | B36: 9% aggregate | C36: =Tax_Revenue_2024!D8 -> 33.003 | D36: ACTIVE | E36: Approved marginal schedule through $1M
A37: Employer SS on capital wages | B37: 3% | C37: =Equity_Compensation!D6 -> 11.001 | D37: ACTIVE | E37: Equity compensation covered at fair value
A38: NHDC mature international export margin
A39: Small Business Surge Reserve | B39: Standing reserve | C39: =-Deficit_Views!B22 -> -10 | D39: ACTIVE COST | E39: General Government obligation
A40: Idle Wealth Levy | B40: 1% central certified base | C40: =Tax_Revenue_2024!D20 -> 47.714505 | D40: ACTIVE | E40: Concentrated nonproductive financial reserves; managers withhold for clients; no cross-tier credit
A41: Total Government Revenue | B41: Presentation control | C41: =Total_Government_Revenue!B19 -> 6 | D41: ACTIVE VIEW | E41: Includes dedicated CWF royalty once; excludes private HSAs
A42: Offshore Capital Export Duty | B42: 10% central behavioral score | C42: =Offshore_Capital_Duty!F12 -> 19.2 | D42: ACTIVE | E42: Passive outbound capital; bona fide U.S. foreign expansion carved out
A43: High-Wealth Withholding Recovery | B43: Collection mechanism | C43: =High_Wealth_Compliance!F9 -> 38 | D43: ACTIVE | E43: Existing liabilities collected through controlled intermediaries
...

Sheet Sources
A1: Sources - Plain URLs Used
A3: Topic | B3: Source | C3: URL | D3: Notes
A4: Personal income | B4: FRED/BEA | C4: https://fred.stlouisfed.org/series/A065RC1A027NBEA | D4: 2024 and modern annual values
A5: GNI | B5: World Bank/FRED | C5: https://fred.stlouisfed.org/series/MKTGNIUSA646NWDB | D5: 2024 and modern values
A6: Wages/salaries | B6: FRED/BEA | C6: https://fred.stlouisfed.org/series/BA06RC1A027NBEA | D6: 2024 payroll base
A7: Corporate profits | B7: FRED/BEA | C7: https://fred.stlouisfed.org/series/A053RC1A027NBEA | D7: 2024 and modern profits
